<?xml version="1.0"?>
<robot name="optimized_complex_robot">

    <!-- Base Link -->
    <link name="base">
        <visual>
            <geometry>
                <box size="0.2 0.2 0.1"/>
            </geometry>
        </visual>
    </link>

    <!-- Link 1 (30mm) -->
    <link name="link1">
        <visual>
            <geometry>
                <cylinder radius="0.02" length="0.03"/> <!-- Length adjusted to 30mm -->
            </geometry>
            <origin xyz="0 0 0.015" rpy="0 0 0"/>  <!-- Centered along length -->
        </visual>
    </link>

    <!-- Joint 1 - Allows 360 degree rotation -->
    <joint name="joint1" type="revolute">
        <parent link="base"/>
        <child link="link1"/>
        <origin xyz="0 0 0.05" rpy="0 0 0"/>
        <axis xyz="0 0 1"/>
        <limit lower="-3.14159" upper="3.14159" effort="1000" velocity="1.0"/>
    </joint>

    <!-- Link 2 (250mm) -->
    <link name="link2">
        <visual>
            <geometry>
                <cylinder radius="0.02" length="0.25"/> <!-- Length adjusted to 250mm -->
            </geometry>
            <origin xyz="0 0 0.125" rpy="0 0 0"/>  <!-- Centered along length -->
        </visual>
    </link>

    <!-- Joint 2 -->
    <joint name="joint2" type="revolute">
        <parent link="link1"/>
        <child link="link2"/>
        <origin xyz="0 0 0.03" rpy="0 0 0"/>  <!-- Adjusted for the length of link1 -->
        <axis xyz="0 1 0"/>
        <limit lower="-1.5708" upper="1.5708" effort="1000" velocity="1.0"/>
    </joint>

    <!-- Link 3 (280mm) -->
    <link name="link3">
        <visual>
            <geometry>
                <cylinder radius="0.02" length="0.28"/> <!-- Length adjusted to 280mm -->
            </geometry>
            <origin xyz="0 0 0.14" rpy="0 0 0"/>  <!-- Centered along length -->
        </visual>
    </link>

    <!-- Joint 3 -->
    <joint name="joint3" type="revolute">
        <parent link="link2"/>
        <child link="link3"/>
        <origin xyz="0 0 0.25" rpy="0 0 0"/>  <!-- Adjusted for the length of link2 -->
        <axis xyz="0 1 0"/>
        <limit lower="-1.5708" upper="1.5708" effort="1000" velocity="1.0"/>
    </joint>

    <!-- Link 4 (280mm) -->
    <link name="link4">
        <visual>
            <geometry>
                <cylinder radius="0.02" length="0.28"/> <!-- Length adjusted to 280mm -->
            </geometry>
            <origin xyz="0 0 0.14" rpy="0 0 0"/>  <!-- Centered along length -->
        </visual>
    </link>

    <!-- Joint 4 -->
    <joint name="joint4" type="revolute">
        <parent link="link3"/>
        <child link="link4"/>
        <origin xyz="0 0 0.28" rpy="0 0 0"/>  <!-- Adjusted for the length of link3 -->
        <axis xyz="0 1 0"/>
        <limit lower="-1.5708" upper="1.5708" effort="1000" velocity="1.0"/>
    </joint>

    <!-- Link 5 -->
    <link name="link5">
        <visual>
            <geometry>
                <cylinder radius="0.02" length="0.15"/> <!-- Maintained as previously specified -->
            </geometry>
            <origin xyz="0 0 0.075" rpy="0 0 0"/>  <!-- Centered along length -->
        </visual>
    </link>

    <!-- Joint 5 -->
    <joint name="joint5" type="revolute">
        <parent link="link4"/>
        <child link="link5"/>
        <origin xyz="0 0 0.28" rpy="0 0 0"/>  <!-- Adjusted for the length of link4 -->
        <axis xyz="0 1 0"/>
        <limit lower="-1.5708" upper="1.5708" effort="1000" velocity="1.0"/>
    </joint>

</robot>
