<?xml version="1.0"?>
<robot name="complex_robot">

    <!-- Base Link -->
    <link name="base">
        <visual>
            <geometry>
                <box size="0.2 0.2 0.1"/>
            </geometry>
        </visual>
    </link>

    <!-- Link 1 -->
    <link name="link1">
        <visual>
            <geometry>
                <cylinder radius="0.02" length="0.4"/>
            </geometry>
            <origin xyz="0 0 0.2" rpy="0 0 0"/>  <!-- Centered along length -->
        </visual>
    </link>

    <!-- Joint 1 - Allows 360 degree rotation -->
    <joint name="joint1" type="revolute">
        <parent link="base"/>
        <child link="link1"/>
        <origin xyz="0 0 0.05" rpy="0 0 0"/>
        <axis xyz="0 0 1"/>
        <limit lower="-3.14159" upper="3.14159" effort="1000" velocity="1.0"/>
    </joint>

    <!-- Link 2 -->
    <link name="link2">
        <visual>
            <geometry>
                <cylinder radius="0.02" length="0.3"/>
            </geometry>
            <origin xyz="0 0 0.15" rpy="0 0 0"/>  <!-- Centered along length -->
        </visual>
    </link>

    <!-- Joint 2 to 5 share the same rotation axis and are defined similarly -->
    <joint name="joint2" type="revolute">
        <parent link="link1"/>
        <child link="link2"/>
        <origin xyz="0 0 0.4" rpy="0 0 0"/>
        <axis xyz="0 1 0"/>
        <limit lower="-1.5708" upper="1.5708" effort="1000" velocity="1.0"/>
    </joint>

    <!-- Subsequent links and joints are defined in a chain with identical joint parameters -->
    <!-- Link 3 -->
    <link name="link3">
        <visual>
            <geometry>
                <cylinder radius="0.02" length="0.25"/>
            </geometry>
            <origin xyz="0 0 0.125" rpy="0 0 0"/>  <!-- Centered along length -->
        </visual>
    </link>

    <!-- Joint 3 -->
    <joint name="joint3" type="revolute">
        <parent link="link2"/>
        <child link="link3"/>
        <origin xyz="0 0 0.3" rpy="0 0 0"/>
        <axis xyz="0 1 0"/>
        <limit lower="-1.5708" upper="1.5708" effort="1000" velocity="1.0"/>
    </joint>

    <!-- Link 4 -->
    <link name="link4">
        <visual>
            <geometry>
                <cylinder radius="0.02" length="0.2"/>
            </geometry>
            <origin xyz="0 0 0.1" rpy="0 0 0"/>  <!-- Centered along length -->
        </visual>
    </link>

    <!-- Joint 4 -->
    <joint name="joint4" type="revolute">
        <parent link="link3"/>
        <child link="link4"/>
        <origin xyz="0 0 0.25" rpy="0 0 0"/>
        <axis xyz="0 1 0"/>
        <limit lower="-1.5708" upper="1.5708" effort="1000" velocity="1.0"/>
    </joint>

    <!-- Link 5 -->
    <link name="link5">
        <visual>
            <geometry>
                <cylinder radius="0.02" length="0.15"/>
            </geometry>
            <origin xyz="0 0 0.075" rpy="0 0 0"/>  <!-- Centered along length -->
        </visual>
    </link>

    <!-- Joint 5 -->
    <joint name="joint5" type="revolute">
        <parent link="link4"/>
        <child link="link5"/>
        <origin xyz="0 0 0.2" rpy="0 0 0"/>
        <axis xyz="0 1 0"/>
        <limit lower="-1.5708" upper="1.5708" effort="1000" velocity="1.0"/>
    </joint>

</robot>
